Workbook

Sheet Sheet1
A1: 30_yr_market_data
A2: Date | B2: Nasdaq | C2: NYSE Composite | D2: S&P500 | E2: CBOE Volitility | F2: Amazon | G2: Apple | H2: Exxon | I2: Google | J2: Tesla | K2: Crude Oil-WTI | L2: Gold | M2: nasdaq_return | N2: nyse_return | O2: sp500_return | P2: amazon_return | Q2: apple_return | R2: exxon_return | S2: google_return | T2: tesla_return | U2: oil_return | V2: gold_return | W2: sp500_volatility_5d | X2: risk
A3: 34701 | M3: =IF(OR(B3="",B2=""),"",B3/B2-1) | N3: =IF(OR(C3="",C2=""),"",C3/C2-1) | O3: =IF(OR(D3="",D2=""),"",D3/D2-1) | P3: =IF(OR(F3="",F2=""),"",F3/F2-1) | Q3: =IF(OR(G3="",G2=""),"",G3/G2-1) | R3: =IF(OR(H3="",H2=""),"",H3/H2-1) | S3: =IF(OR(I3="",I2=""),"",I3/I2-1) | T3: =IF(OR(J3="",J2=""),"",J3/J2-1) | U3: =IF(OR(K3="",K2=""),"",K3/K2-1) | V3: =IF(OR(L3="",L2=""),"",L3/L2-1)
A4: 34702 | B4: 743.58 | C4: 2651.15 | D4: 459.11 | E4: 14.25 | G4: 0.28 | H4: 5.72 | M4: =IF(OR(B4="",B3=""),"",B4/B3-1) | N4: =IF(OR(C4="",C3=""),"",C4/C3-1) | O4: =IF(OR(D4="",D3=""),"",D4/D3-1) | P4: =IF(OR(F4="",F3=""),"",F4/F3-1) | Q4: =IF(OR(G4="",G3=""),"",G4/G3-1) | R4: =IF(OR(H4="",H3=""),"",H4/H3-1) | S4: =IF(OR(I4="",I3=""),"",I4/I3-1) | T4: =IF(OR(J4="",J3=""),"",J4/J3-1) | U4: =IF(OR(K4="",K3=""),"",K4/K3-1) | V4: =IF(OR(L4="",L3=""),"",L4/L3-1)
A5: 34703 | B5: 745.84 | C5: 2658.87 | D5: 460.71 | E5: 13.53 | G5: 0.29 | H5: 5.75 | M5: =IF(OR(B5="",B4=""),"",B5/B4-1) -> 0.0030393502 | N5: =IF(OR(C5="",C4=""),"",C5/C4-1) -> 0.0029119439 | O5: =IF(OR(D5="",D4=""),"",D5/D4-1) -> 0.0034850036 | P5: =IF(OR(F5="",F4=""),"",F5/F4-1) | Q5: =IF(OR(G5="",G4=""),"",G5/G4-1) -> 0.035714286 | R5: =IF(OR(H5="",H4=""),"",H5/H4-1) -> 0.0052447552 | S5: =IF(OR(I5="",I4=""),"",I5/I4-1) | T5: =IF(OR(J5="",J4=""),"",J5/J4-1) | U5: =IF(OR(K5="",K4=""),"",K5/K4-1) | V5: =IF(OR(L5="",L4=""),"",L5/L4-1)
A6: 34704 | B6: 745.66 | C6: 2658.13 | D6: 460.34 | E6: 13.5 | G6: 0.29 | H6: 5.76 | M6: =IF(OR(B6="",B5=""),"",B6/B5-1) -> -0.00024133862 | N6: =IF(OR(C6="",C5=""),"",C6/C5-1) -> -0.00027831372 | O6: =IF(OR(D6="",D5=""),"",D6/D5-1) -> -0.00080310825 | P6: =IF(OR(F6="",F5=""),"",F6/F5-1) | Q6: =IF(OR(G6="",G5=""),"",G6/G5-1) -> 0 | R6: =IF(OR(H6="",H5=""),"",H6/H5-1) -> 0.0017391304 | S6: =IF(OR(I6="",I5=""),"",I6/I5-1) | T6: =IF(OR(J6="",J5=""),"",J6/J5-1) | U6: =IF(OR(K6="",K5=""),"",K6/K5-1) | V6: =IF(OR(L6="",L5=""),"",L6/L5-1)
A7: 34705 | B7: 749.69 | C7: 2660.24 | D7: 460.68 | E7: 13.13 | G7: 0.31 | H7: 5.76 | M7: =IF(OR(B7="",B6=""),"",B7/B6-1) -> 0.005404608 | N7: =IF(OR(C7="",C6=""),"",C7/C6-1) -> 0.00079379112 | O7: =IF(OR(D7="",D6=""),"",D7/D6-1) -> 0.00073858452 | P7: =IF(OR(F7="",F6=""),"",F7/F6-1) | Q7: =IF(OR(G7="",G6=""),"",G7/G6-1) -> 0.068965517 | R7: =IF(OR(H7="",H6=""),"",H7/H6-1) -> 0 | S7: =IF(OR(I7="",I6=""),"",I7/I6-1) | T7: =IF(OR(J7="",J6=""),"",J7/J6-1) | U7: =IF(OR(K7="",K6=""),"",K7/K6-1) | V7: =IF(OR(L7="",L6=""),"",L7/L6-1)
A8: 34708 | B8: 752.09 | C8: 2660.14 | D8: 460.83 | E8: 13.33 | G8: 0.31 | H8: 5.71 | M8: =IF(OR(B8="",B7=""),"",B8/B7-1) -> 0.0032013232 | N8: =IF(OR(C8="",C7=""),"",C8/C7-1) -> -3.7590593e-05 | O8: =IF(OR(D8="",D7=""),"",D8/D7-1) -> 0.00032560563 | P8: =IF(OR(F8="",F7=""),"",F8/F7-1) | Q8: =IF(OR(G8="",G7=""),"",G8/G7-1) -> 0 | R8: =IF(OR(H8="",H7=""),"",H8/H7-1) -> -0.0086805556 | S8: =IF(OR(I8="",I7=""),"",I8/I7-1) | T8: =IF(OR(J8="",J7=""),"",J8/J7-1) | U8: =IF(OR(K8="",K7=""),"",K8/K7-1) | V8: =IF(OR(L8="",L7=""),"",L8/L7-1) | W8: =IF(COUNT(O4:O8)<5,"",STDEV(O4:O8)) | X8: =IF(W8="","",IF(W8>Controls!$B$2,1,0))
A9: 34709 | B9: 756.52 | C9: 2661.3 | D9: 461.68 | E9: 12.52 | G9: 0.32 | H9: 5.74 | M9: =IF(OR(B9="",B8=""),"",B9/B8-1) -> 0.0058902525 | N9: =IF(OR(C9="",C8=""),"",C9/C8-1) -> 0.00043606727 | O9: =IF(OR(D9="",D8=""),"",D9/D8-1) -> 0.001844498 | P9: =IF(OR(F9="",F8=""),"",F9/F8-1) | Q9: =IF(OR(G9="",G8=""),"",G9/G8-1) -> 0.032258065 | R9: =IF(OR(H9="",H8=""),"",H9/H8-1) -> 0.0052539405 | S9: =IF(OR(I9="",I8=""),"",I9/I8-1) | T9: =IF(OR(J9="",J8=""),"",J9/J8-1) | U9: =IF(OR(K9="",K8=""),"",K9/K8-1) | V9: =IF(OR(L9="",L8=""),"",L9/L8-1) | W9: =IF(COUNT(O5:O9)<5,"",STDEV(O5:O9)) -> 0.001627345 | X9: =IF(W9="","",IF(W9>Controls!$B$2,1,0)) -> 0
A10: 34710 | B10: 755.74 | C10: 2661.62 | D10: 461.66 | E10: 12.15 | G10: 0.35 | H10: 5.7 | M10: =IF(OR(B10="",B9=""),"",B10/B9-1) -> -0.0010310369 | N10: =IF(OR(C10="",C9=""),"",C10/C9-1) -> 0.00012024199 | O10: =IF(OR(D10="",D9=""),"",D10/D9-1) -> -4.3320049e-05 | P10: =IF(OR(F10="",F9=""),"",F10/F9-1) | Q10: =IF(OR(G10="",G9=""),"",G10/G9-1) -> 0.09375 | R10: =IF(OR(H10="",H9=""),"",H10/H9-1) -> -0.0069686411 | S10: =IF(OR(I10="",I9=""),"",I10/I9-1) | T10: =IF(OR(J10="",J9=""),"",J10/J9-1) | U10: =IF(OR(K10="",K9=""),"",K10/K9-1) | V10: =IF(OR(L10="",L9=""),"",L10/L9-1) | W10: =IF(COUNT(O6:O10)<5,"",STDEV(O6:O10)) -> 0.00098106769 | X10: =IF(W10="","",IF(W10>Controls!$B$2,1,0)) -> 0
A11: 34711 | B11: 756.51 | C11: 2661.62 | D11: 461.64 | E11: 12.83 | G11: 0.34 | H11: 5.7 | M11: =IF(OR(B11="",B10=""),"",B11/B10-1) -> 0.0010188689 | N11: =IF(OR(C11="",C10=""),"",C11/C10-1) -> 0 | O11: =IF(OR(D11="",D10=""),"",D11/D10-1) -> -4.3321925e-05 | P11: =IF(OR(F11="",F10=""),"",F11/F10-1) | Q11: =IF(OR(G11="",G10=""),"",G11/G10-1) -> -0.028571429 | R11: =IF(OR(H11="",H10=""),"",H11/H10-1) -> 0 | S11: =IF(OR(I11="",I10=""),"",I11/I10-1) | T11: =IF(OR(J11="",J10=""),"",J11/J10-1) | U11: =IF(OR(K11="",K10=""),"",K11/K10-1) | V11: =IF(OR(L11="",L10=""),"",L11/L10-1) | W11: =IF(COUNT(O7:O11)<5,"",STDEV(O7:O11)) -> 0.00078496233 | X11: =IF(W11="","",IF(W11>Controls!$B$2,1,0)) -> 0
A12: 34712 | B12: 762.16 | C12: 2685.2 | D12: 465.97 | E12: 11.1 | G12: 0.33 | H12: 5.75 | M12: =IF(OR(B12="",B11=""),"",B12/B11-1) -> 0.0074685067 | N12: =IF(OR(C12="",C11=""),"",C12/C11-1) -> 0.0088592662 | O12: =IF(OR(D12="",D11=""),"",D12/D11-1) -> 0.0093796032 | P12: =IF(OR(F12="",F11=""),"",F12/F11-1) | Q12: =IF(OR(G12="",G11=""),"",G12/G11-1) -> -0.029411765 | R12: =IF(OR(H12="",H11=""),"",H12/H11-1) -> 0.0087719298 | S12: =IF(OR(I12="",I11=""),"",I12/I11-1) | T12: =IF(OR(J12="",J11=""),"",J12/J11-1) | U12: =IF(OR(K12="",K11=""),"",K12/K11-1) | V12: =IF(OR(L12="",L11=""),"",L12/L11-1) | W12: =IF(COUNT(O8:O12)<5,"",STDEV(O8:O12)) -> 0.0040375899 | X12: =IF(W12="","",IF(W12>Controls!$B$2,1,0)) -> 0
A13: 34715 | B13: 768.16 | C13: 2704.87 | D13: 469.38 | E13: 11.14 | G13: 0.33 | H13: 5.74 | M13: =IF(OR(B13="",B12=""),"",B13/B12-1) -> 0.0078723628 | N13: =IF(OR(C13="",C12=""),"",C13/C12-1) -> 0.0073253389 | O13: =IF(OR(D13="",D12=""),"",D13/D12-1) -> 0.0073180677 | P13: =IF(OR(F13="",F12=""),"",F13/F12-1) | Q13: =IF(OR(G13="",G12=""),"",G13/G12-1) -> 0 | R13: =IF(OR(H13="",H12=""),"",H13/H12-1) -> -0.0017391304 | S13: =IF(OR(I13="",I12=""),"",I13/I12-1) | T13: =IF(OR(J13="",J12=""),"",J13/J12-1) | U13: =IF(OR(K13="",K12=""),"",K13/K12-1) | V13: =IF(OR(L13="",L12=""),"",L13/L12-1) | W13: =IF(COUNT(O9:O13)<5,"",STDEV(O9:O13)) -> 0.0043822284 | X13: =IF(W13="","",IF(W13>Controls!$B$2,1,0)) -> 0
A14: 34716 | B14: 772.14 | C14: 2709.52 | D14: 470.05 | E14: 11.79 | G14: 0.33 | H14: 5.8 | M14: =IF(OR(B14="",B13=""),"",B14/B13-1) -> 0.0051812122 | N14: =IF(OR(C14="",C13=""),"",C14/C13-1) -> 0.0017191214 | O14: =IF(OR(D14="",D13=""),"",D14/D13-1) -> 0.0014274149 | P14: =IF(OR(F14="",F13=""),"",F14/F13-1) | Q14: =IF(OR(G14="",G13=""),"",G14/G13-1) -> 0 | R14: =IF(OR(H14="",H13=""),"",H14/H13-1) -> 0.010452962 | S14: =IF(OR(I14="",I13=""),"",I14/I13-1) | T14: =IF(OR(J14="",J13=""),"",J14/J13-1) | U14: =IF(OR(K14="",K13=""),"",K14/K13-1) | V14: =IF(OR(L14="",L13=""),"",L14/L13-1) | W14: =IF(COUNT(O10:O14)<5,"",STDEV(O10:O14)) -> 0.0044298771 | X14: =IF(W14="","",IF(W14>Controls!$B$2,1,0)) -> 0
A15: 34717 | B15: 772.38 | C15: 2706.56 | D15: 469.71 | E15: 11.57 | G15: 0.34 | H15: 5.87 | M15: =IF(OR(B15="",B14=""),"",B15/B14-1) -> 0.00031082446 | N15: =IF(OR(C15="",C14=""),"",C15/C14-1) -> -0.0010924444 | O15: =IF(OR(D15="",D14=""),"",D15/D14-1) -> -0.00072332731 | P15: =IF(OR(F15="",F14=""),"",F15/F14-1) | Q15: =IF(OR(G15="",G14=""),"",G15/G14-1) -> 0.03030303 | R15: =IF(OR(H15="",H14=""),"",H15/H14-1) -> 0.012068966 | S15: =IF(OR(I15="",I14=""),"",I15/I14-1) | T15: =IF(OR(J15="",J14=""),"",J15/J14-1) | U15: =IF(OR(K15="",K14=""),"",K15/K14-1) | V15: =IF(OR(L15="",L14=""),"",L15/L14-1) | W15: =IF(COUNT(O11:O15)<5,"",STDEV(O11:O15)) -> 0.0045779526 | X15: =IF(W15="","",IF(W15>Controls!$B$2,1,0)) -> 0
A16: 34718 | B16: 768.55 | C16: 2689.75 | D16: 466.95 | E16: 11.86 | G16: 0.34 | H16: 5.87 | M16: =IF(OR(B16="",B15=""),"",B16/B15-1) -> -0.0049586991 | N16: =IF(OR(C16="",C15=""),"",C16/C15-1) -> -0.0062108359 | O16: =IF(OR(D16="",D15=""),"",D16/D15-1) -> -0.005875966 | P16: =IF(OR(F16="",F15=""),"",F16/F15-1) | Q16: =IF(OR(G16="",G15=""),"",G16/G15-1) -> 0 | R16: =IF(OR(H16="",H15=""),"",H16/H15-1) -> 0 | S16: =IF(OR(I16="",I15=""),"",I16/I15-1) | T16: =IF(OR(J16="",J15=""),"",J16/J15-1) | U16: =IF(OR(K16="",K15=""),"",K16/K15-1) | V16: =IF(OR(L16="",L15=""),"",L16/L15-1) | W16: =IF(COUNT(O12:O16)<5,"",STDEV(O12:O16)) -> 0.0061654275 | X16: =IF(W16="","",IF(W16>Controls!$B$2,1,0)) -> 0
A17: 34719 | B17: 762.05 | C17: 2679.17 | D17: 464.78 | E17: 12.15 | G17: 0.32 | H17: 5.93 | M17: =IF(OR(B17="",B16=""),"",B17/B16-1) -> -0.0084574849 | N17: =IF(OR(C17="",C16=""),"",C17/C16-1) -> -0.0039334511 | O17: =IF(OR(D17="",D16=""),"",D17/D16-1) -> -0.0046471785 | P17: =IF(OR(F17="",F16=""),"",F17/F16-1) | Q17: =IF(OR(G17="",G16=""),"",G17/G16-1) -> -0.058823529 | R17: =IF(OR(H17="",H16=""),"",H17/H16-1) -> 0.010221465 | S17: =IF(OR(I17="",I16=""),"",I17/I16-1) | T17: =IF(OR(J17="",J16=""),"",J17/J16-1) | U17: =IF(OR(K17="",K16=""),"",K17/K16-1) | V17: =IF(OR(L17="",L16=""),"",L17/L16-1) | W17: =IF(COUNT(O13:O17)<5,"",STDEV(O13:O17)) -> 0.0052675204 | X17: =IF(W17="","",IF(W17>Controls!$B$2,1,0)) -> 0
A18: 34722 | B18: 759.51 | C18: 2680.12 | D18: 465.82 | E18: 12.79 | G18: 0.31 | H18: 6.02 | M18: =IF(OR(B18="",B17=""),"",B18/B17-1) -> -0.0033331146 | N18: =IF(OR(C18="",C17=""),"",C18/C17-1) -> 0.00035458743 | O18: =IF(OR(D18="",D17=""),"",D18/D17-1) -> 0.0022376178 | P18: =IF(OR(F18="",F17=""),"",F18/F17-1) | Q18: =IF(OR(G18="",G17=""),"",G18/G17-1) -> -0.03125 | R18: =IF(OR(H18="",H17=""),"",H18/H17-1) -> 0.015177066 | S18: =IF(OR(I18="",I17=""),"",I18/I17-1) | T18: =IF(OR(J18="",J17=""),"",J18/J17-1) | U18: =IF(OR(K18="",K17=""),"",K18/K17-1) | V18: =IF(OR(L18="",L17=""),"",L18/L17-1) | W18: =IF(COUNT(O14:O18)<5,"",STDEV(O14:O18)) -> 0.003612314 | X18: =IF(W18="","",IF(W18>Controls!$B$2,1,0)) -> 0
A19: 34723 | B19: 763.2 | C19: 2682.56 | D19: 465.86 | E19: 11.94 | G19: 0.31 | H19: 5.9 | M19: =IF(OR(B19="",B18=""),"",B19/B18-1) -> 0.0048583955 | N19: =IF(OR(C19="",C18=""),"",C19/C18-1) -> 0.000910407 | O19: =IF(OR(D19="",D18=""),"",D19/D18-1) -> 8.5870079e-05 | P19: =IF(OR(F19="",F18=""),"",F19/F18-1) | Q19: =IF(OR(G19="",G18=""),"",G19/G18-1) -> 0 | R19: =IF(OR(H19="",H18=""),"",H19/H18-1) -> -0.019933555 | S19: =IF(OR(I19="",I18=""),"",I19/I18-1) | T19: =IF(OR(J19="",J18=""),"",J19/J18-1) | U19: =IF(OR(K19="",K18=""),"",K19/K18-1) | V19: =IF(OR(L19="",L18=""),"",L19/L18-1) | W19: =IF(COUNT(O15:O19)<5,"",STDEV(O15:O19)) -> 0.0033814503 | X19: =IF(W19="","",IF(W19>Controls!$B$2,1,0)) -> 0
... A37: 34747 | B37: 786.97 | C37: 2768.52 | D37: 481.97 | E37: 11.71 | G37: 0.32 | H37: 6.06 | M37: =IF(OR(B37="",B36=""),"",B37/B36-1) -> -0.0079918317 | N37: =IF(OR(C37="",C36=""),"",C37/C36-1) -> -0.0054710373 | O37: =IF(OR(D37="",D36=""),"",D37/D36-1) -> -0.0066979927 | P37: =IF(OR(F37="",F36=""),"",F37/F36-1) | Q37: =IF(OR(G37="",G36=""),"",G37/G36-1) -> 0 | R37: =IF(OR(H37="",H36=""),"",H37/H36-1) -> -0.0098039216 | S37: =IF(OR(I37="",I36=""),"",I37/I36-1) | T37: =IF(OR(J37="",J36=""),"",J37/J36-1) | U37: =IF(OR(K37="",K36=""),"",K37/K36-1) | V37: =IF(OR(L37="",L36=""),"",L37/L36-1) | W37: =IF(COUNT(O33:O37)<5,"",STDEV(O33:O37)) -> 0.0041002427 | X37: =IF(W37="","",IF(W37>Controls!$B$2,1,0)) -> 0
A38: 34750 | M38: =IF(OR(B38="",B37=""),"",B38/B37-1) | N38: =IF(OR(C38="",C37=""),"",C38/C37-1) | O38: =IF(OR(D38="",D37=""),"",D38/D37-1) | P38: =IF(OR(F38="",F37=""),"",F38/F37-1) | Q38: =IF(OR(G38="",G37=""),"",G38/G37-1) | R38: =IF(OR(H38="",H37=""),"",H38/H37-1) | S38: =IF(OR(I38="",I37=""),"",I38/I37-1) | T38: =IF(OR(J38="",J37=""),"",J38/J37-1) | U38: =IF(OR(K38="",K37=""),"",K38/K37-1) | V38: =IF(OR(L38="",L37=""),"",L38/L37-1) | W38: =IF(COUNT(O34:O38)<5,"",STDEV(O34:O38)) | X38: =IF(W38="","",IF(W38>Controls!$B$2,1,0))
A39: 34751 | B39: 784.62 | C39: 2770.11 | D39: 482.72 | E39: 12.05 | G39: 0.3 | H39: 6.12 | M39: =IF(OR(B39="",B38=""),"",B39/B38-1) | N39: =IF(OR(C39="",C38=""),"",C39/C38-1) | O39: =IF(OR(D39="",D38=""),"",D39/D38-1) | P39: =IF(OR(F39="",F38=""),"",F39/F38-1) | Q39: =IF(OR(G39="",G38=""),"",G39/G38-1) | R39: =IF(OR(H39="",H38=""),"",H39/H38-1) | S39: =IF(OR(I39="",I38=""),"",I39/I38-1) | T39: =IF(OR(J39="",J38=""),"",J39/J38-1) | U39: =IF(OR(K39="",K38=""),"",K39/K38-1) | V39: =IF(OR(L39="",L38=""),"",L39/L38-1) | W39: =IF(COUNT(O35:O39)<5,"",STDEV(O35:O39)) | X39: =IF(W39="","",IF(W39>Controls!$B$2,1,0))
A40: 34752 | B40: 787.93 | C40: 2781.31 | D40: 485.07 | E40: 11.39 | G40: 0.3 | H40: 6.13 | M40: =IF(OR(B40="",B39=""),"",B40/B39-1) -> 0.0042186026 | N40: =IF(OR(C40="",C39=""),"",C40/C39-1) -> 0.0040431607 | O40: =IF(OR(D40="",D39=""),"",D40/D39-1) -> 0.0048682466 | P40: =IF(OR(F40="",F39=""),"",F40/F39-1) | Q40: =IF(OR(G40="",G39=""),"",G40/G39-1) -> 0 | R40: =IF(OR(H40="",H39=""),"",H40/H39-1) -> 0.0016339869 | S40: =IF(OR(I40="",I39=""),"",I40/I39-1) | T40: =IF(OR(J40="",J39=""),"",J40/J39-1) | U40: =IF(OR(K40="",K39=""),"",K40/K39-1) | V40: =IF(OR(L40="",L39=""),"",L40/L39-1) | W40: =IF(COUNT(O36:O40)<5,"",STDEV(O36:O40)) | X40: =IF(W40="","",IF(W40>Controls!$B$2,1,0))
A41: 34753 | B41: 791.35 | C41: 2794 | D41: 486.91 | E41: 11.15 | G41: 0.3 | H41: 6.09 | M41: =IF(OR(B41="",B40=""),"",B41/B40-1) -> 0.0043404871 | N41: =IF(OR(C41="",C40=""),"",C41/C40-1) -> 0.0045625982 | O41: =IF(OR(D41="",D40=""),"",D41/D40-1) -> 0.003793267 | P41: =IF(OR(F41="",F40=""),"",F41/F40-1) | Q41: =IF(OR(G41="",G40=""),"",G41/G40-1) -> 0 | R41: =IF(OR(H41="",H40=""),"",H41/H40-1) -> -0.0065252855 | S41: =IF(OR(I41="",I40=""),"",I41/I40-1) | T41: =IF(OR(J41="",J40=""),"",J41/J40-1) | U41: =IF(OR(K41="",K40=""),"",K41/K40-1) | V41: =IF(OR(L41="",L40=""),"",L41/L40-1) | W41: =IF(COUNT(O37:O41)<5,"",STDEV(O37:O41)) | X41: =IF(W41="","",IF(W41>Controls!$B$2,1,0))
A42: 34754 | B42: 791.08 | C42: 2800.56 | D42: 488.11 | E42: 10.84 | G42: 0.29 | H42: 6.06 | M42: =IF(OR(B42="",B41=""),"",B42/B41-1) -> -0.00034118911 | N42: =IF(OR(C42="",C41=""),"",C42/C41-1) -> 0.0023478883 | O42: =IF(OR(D42="",D41=""),"",D42/D41-1) -> 0.0024645212 | P42: =IF(OR(F42="",F41=""),"",F42/F41-1) | Q42: =IF(OR(G42="",G41=""),"",G42/G41-1) -> -0.033333333 | R42: =IF(OR(H42="",H41=""),"",H42/H41-1) -> -0.0049261084 | S42: =IF(OR(I42="",I41=""),"",I42/I41-1) | T42: =IF(OR(J42="",J41=""),"",J42/J41-1) | U42: =IF(OR(K42="",K41=""),"",K42/K41-1) | V42: =IF(OR(L42="",L41=""),"",L42/L41-1) | W42: =IF(COUNT(O38:O42)<5,"",STDEV(O38:O42)) | X42: =IF(W42="","",IF(W42>Controls!$B$2,1,0))
A43: 34757 | B43: 784.5 | C43: 2777.51 | D43: 483.81 | E43: 12.51 | G43: 0.28 | H43: 6.08 | M43: =IF(OR(B43="",B42=""),"",B43/B42-1) -> -0.0083177428 | N43: =IF(OR(C43="",C42=""),"",C43/C42-1) -> -0.0082304968 | O43: =IF(OR(D43="",D42=""),"",D43/D42-1) -> -0.0088094897 | P43: =IF(OR(F43="",F42=""),"",F43/F42-1) | Q43: =IF(OR(G43="",G42=""),"",G43/G42-1) -> -0.034482759 | R43: =IF(OR(H43="",H42=""),"",H43/H42-1) -> 0.00330033 | S43: =IF(OR(I43="",I42=""),"",I43/I42-1) | T43: =IF(OR(J43="",J42=""),"",J43/J42-1) | U43: =IF(OR(K43="",K42=""),"",K43/K42-1) | V43: =IF(OR(L43="",L42=""),"",L43/L42-1) | W43: =IF(COUNT(O39:O43)<5,"",STDEV(O39:O43)) | X43: =IF(W43="","",IF(W43>Controls!$B$2,1,0))
A44: 34758 | B44: 793.73 | C44: 2798.34 | D44: 487.39 | E44: 11.75 | G44: 0.29 | H44: 6.1 | M44: =IF(OR(B44="",B43=""),"",B44/B43-1) -> 0.011765456 | N44: =IF(OR(C44="",C43=""),"",C44/C43-1) -> 0.007499523 | O44: =IF(OR(D44="",D43=""),"",D44/D43-1) -> 0.007399599 | P44: =IF(OR(F44="",F43=""),"",F44/F43-1) | Q44: =IF(OR(G44="",G43=""),"",G44/G43-1) -> 0.035714286 | R44: =IF(OR(H44="",H43=""),"",H44/H43-1) -> 0.0032894737 | S44: =IF(OR(I44="",I43=""),"",I44/I43-1) | T44: =IF(OR(J44="",J43=""),"",J44/J43-1) | U44: =IF(OR(K44="",K43=""),"",K44/K43-1) | V44: =IF(OR(L44="",L43=""),"",L44/L43-1) | W44: =IF(COUNT(O40:O44)<5,"",STDEV(O40:O44)) -> 0.0062777991 | X44: =IF(W44="","",IF(W44>Controls!$B$2,1,0)) -> 0
A45: 34759 | B45: 791.87 | C45: 2788.93 | D45: 485.65 | E45: 11.65 | G45: 0.3 | H45: 6.07 | M45: =IF(OR(B45="",B44=""),"",B45/B44-1) -> -0.0023433661 | N45: =IF(OR(C45="",C44=""),"",C45/C44-1) -> -0.0033627079 | O45: =IF(OR(D45="",D44=""),"",D45/D44-1) -> -0.0035700363 | P45: =IF(OR(F45="",F44=""),"",F45/F44-1) | Q45: =IF(OR(G45="",G44=""),"",G45/G44-1) -> 0.034482759 | R45: =IF(OR(H45="",H44=""),"",H45/H44-1) -> -0.0049180328 | S45: =IF(OR(I45="",I44=""),"",I45/I44-1) | T45: =IF(OR(J45="",J44=""),"",J45/J44-1) | U45: =IF(OR(K45="",K44=""),"",K45/K44-1) | V45: =IF(OR(L45="",L44=""),"",L45/L44-1) | W45: =IF(COUNT(O41:O45)<5,"",STDEV(O41:O45)) -> 0.0064273339 | X45: =IF(W45="","",IF(W45>Controls!$B$2,1,0)) -> 0
A46: 34760 | B46: 793.68 | C46: 2784.7 | D46: 485.13 | E46: 12.02 | G46: 0.3 | H46: 6.06 | M46: =IF(OR(B46="",B45=""),"",B46/B45-1) -> 0.0022857287 | N46: =IF(OR(C46="",C45=""),"",C46/C45-1) -> -0.0015167107 | O46: =IF(OR(D46="",D45=""),"",D46/D45-1) -> -0.0010707299 | P46: =IF(OR(F46="",F45=""),"",F46/F45-1) | Q46: =IF(OR(G46="",G45=""),"",G46/G45-1) -> 0 | R46: =IF(OR(H46="",H45=""),"",H46/H45-1) -> -0.0016474465 | S46: =IF(OR(I46="",I45=""),"",I46/I45-1) | T46: =IF(OR(J46="",J45=""),"",J46/J45-1) | U46: =IF(OR(K46="",K45=""),"",K46/K45-1) | V46: =IF(OR(L46="",L45=""),"",L46/L45-1) | W46: =IF(COUNT(O42:O46)<5,"",STDEV(O42:O46)) -> 0.0061187128 | X46: =IF(W46="","",IF(W46>Controls!$B$2,1,0)) -> 0
A47: 34761 | B47: 798.79 | C47: 2783.96 | D47: 485.42 | E47: 11.45 | G47: 0.3 | H47: 6.04 | M47: =IF(OR(B47="",B46=""),"",B47/B46-1) -> 0.0064383631 | N47: =IF(OR(C47="",C46=""),"",C47/C46-1) -> -0.00026573778 | O47: =IF(OR(D47="",D46=""),"",D47/D46-1) -> 0.00059777792 | P47: =IF(OR(F47="",F46=""),"",F47/F46-1) | Q47: =IF(OR(G47="",G46=""),"",G47/G46-1) -> 0 | R47: =IF(OR(H47="",H46=""),"",H47/H46-1) -> -0.00330033 | S47: =IF(OR(I47="",I46=""),"",I47/I46-1) | T47: =IF(OR(J47="",J46=""),"",J47/J46-1) | U47: =IF(OR(K47="",K46=""),"",K47/K46-1) | V47: =IF(OR(L47="",L46=""),"",L47/L46-1) | W47: =IF(COUNT(O43:O47)<5,"",STDEV(O43:O47)) -> 0.0059300792 | X47: =IF(W47="","",IF(W47>Controls!$B$2,1,0)) -> 0
A48: 34764 | B48: 797.77 | C48: 2782.05 | D48: 485.63 | E48: 12.17 | G48: 0.3 | H48: 6.12 | M48: =IF(OR(B48="",B47=""),"",B48/B47-1) -> -0.0012769314 | N48: =IF(OR(C48="",C47=""),"",C48/C47-1) -> -0.00068607308 | O48: =IF(OR(D48="",D47=""),"",D48/D47-1) -> 0.00043261506 | P48: =IF(OR(F48="",F47=""),"",F48/F47-1) | Q48: =IF(OR(G48="",G47=""),"",G48/G47-1) -> 0 | R48: =IF(OR(H48="",H47=""),"",H48/H47-1) -> 0.013245033 | S48: =IF(OR(I48="",I47=""),"",I48/I47-1) | T48: =IF(OR(J48="",J47=""),"",J48/J47-1) | U48: =IF(OR(K48="",K47=""),"",K48/K47-1) | V48: =IF(OR(L48="",L47=""),"",L48/L47-1) | W48: =IF(COUNT(O44:O48)<5,"",STDEV(O44:O48)) -> 0.0040718097 | X48: =IF(W48="","",IF(W48>Controls!$B$2,1,0)) -> 0
A49: 34765 | B49: 791.33 | C49: 2762.39 | D49: 482.12 | E49: 14.22 | G49: 0.28 | H49: 6.12 | M49: =IF(OR(B49="",B48=""),"",B49/B48-1) -> -0.0080725021 | N49: =IF(OR(C49="",C48=""),"",C49/C48-1) -> -0.0070667314 | O49: =IF(OR(D49="",D48=""),"",D49/D48-1) -> -0.0072277248 | P49: =IF(OR(F49="",F48=""),"",F49/F48-1) | Q49: =IF(OR(G49="",G48=""),"",G49/G48-1) -> -0.066666667 | R49: =IF(OR(H49="",H48=""),"",H49/H48-1) -> 0 | S49: =IF(OR(I49="",I48=""),"",I49/I48-1) | T49: =IF(OR(J49="",J48=""),"",J49/J48-1) | U49: =IF(OR(K49="",K48=""),"",K49/K48-1) | V49: =IF(OR(L49="",L48=""),"",L49/L48-1) | W49: =IF(COUNT(O45:O49)<5,"",STDEV(O45:O49)) -> 0.0032856981 | X49: =IF(W49="","",IF(W49>Controls!$B$2,1,0)) -> 0
A50: 34766 | B50: 795.81 | C50: 2766.09 | D50: 483.14 | E50: 13.72 | G50: 0.29 | H50: 6.19 | M50: =IF(OR(B50="",B49=""),"",B50/B49-1) -> 0.0056613549 | N50: =IF(OR(C50="",C49=""),"",C50/C49-1) -> 0.0013394199 | O50: =IF(OR(D50="",D49=""),"",D50/D49-1) -> 0.0021156559 | P50: =IF(OR(F50="",F49=""),"",F50/F49-1) | Q50: =IF(OR(G50="",G49=""),"",G50/G49-1) -> 0.035714286 | R50: =IF(OR(H50="",H49=""),"",H50/H49-1) -> 0.011437908 | S50: =IF(OR(I50="",I49=""),"",I50/I49-1) | T50: =IF(OR(J50="",J49=""),"",J50/J49-1) | U50: =IF(OR(K50="",K49=""),"",K50/K49-1) | V50: =IF(OR(L50="",L49=""),"",L50/L49-1) | W50: =IF(COUNT(O46:O50)<5,"",STDEV(O46:O50)) -> 0.0036434017 | X50: =IF(W50="","",IF(W50>Controls!$B$2,1,0)) -> 0
... A76: 34802 | B76: 832.64 | C76: 2907.78 | D76: 509.23 | E76: 11.48 | G76: 0.28 | H76: 6.42 | M76: =IF(OR(B76="",B75=""),"",B76/B75-1) -> 0.0049605929 | N76: =IF(OR(C76="",C75=""),"",C76/C75-1) -> 0.0035028627 | O76: =IF(OR(D76="",D75=""),"",D76/D75-1) -> 0.0040617544 | P76: =IF(OR(F76="",F75=""),"",F76/F75-1) | Q76: =IF(OR(G76="",G75=""),"",G76/G75-1) -> -0.034482759 | R76: =IF(OR(H76="",H75=""),"",H76/H75-1) -> 0.0046948357 | S76: =IF(OR(I76="",I75=""),"",I76/I75-1) | T76: =IF(OR(J76="",J75=""),"",J76/J75-1) | U76: =IF(OR(K76="",K75=""),"",K76/K75-1) | V76: =IF(OR(L76="",L75=""),"",L76/L75-1) | W76: =IF(COUNT(O72:O76)<5,"",STDEV(O72:O76)) -> 0.0027205248 | X76: =IF(W76="","",IF(W76>Controls!$B$2,1,0)) -> 0
A77: 34803 | M77: =IF(OR(B77="",B76=""),"",B77/B76-1) | N77: =IF(OR(C77="",C76=""),"",C77/C76-1) | O77: =IF(OR(D77="",D76=""),"",D77/D76-1) | P77: =IF(OR(F77="",F76=""),"",F77/F76-1) | Q77: =IF(OR(G77="",G76=""),"",G77/G76-1) | R77: =IF(OR(H77="",H76=""),"",H77/H76-1) | S77: =IF(OR(I77="",I76=""),"",I77/I76-1) | T77: =IF(OR(J77="",J76=""),"",J77/J76-1) | U77: =IF(OR(K77="",K76=""),"",K77/K76-1) | V77: =IF(OR(L77="",L76=""),"",L77/L76-1) | W77: =IF(COUNT(O73:O77)<5,"",STDEV(O73:O77)) | X77: =IF(W77="","",IF(W77>Controls!$B$2,1,0))
A78: 34806 | B78: 830.82 | C78: 2892.34 | D78: 506.13 | E78: 12.33 | G78: 0.29 | H78: 6.43 | M78: =IF(OR(B78="",B77=""),"",B78/B77-1) | N78: =IF(OR(C78="",C77=""),"",C78/C77-1) | O78: =IF(OR(D78="",D77=""),"",D78/D77-1) | P78: =IF(OR(F78="",F77=""),"",F78/F77-1) | Q78: =IF(OR(G78="",G77=""),"",G78/G77-1) | R78: =IF(OR(H78="",H77=""),"",H78/H77-1) | S78: =IF(OR(I78="",I77=""),"",I78/I77-1) | T78: =IF(OR(J78="",J77=""),"",J78/J77-1) | U78: =IF(OR(K78="",K77=""),"",K78/K77-1) | V78: =IF(OR(L78="",L77=""),"",L78/L77-1) | W78: =IF(COUNT(O74:O78)<5,"",STDEV(O74:O78)) | X78: =IF(W78="","",IF(W78>Controls!$B$2,1,0))
A79: 34807 | B79: 825.74 | C79: 2886.95 | D79: 505.37 | E79: 12.96 | G79: 0.28 | H79: 6.5 | M79: =IF(OR(B79="",B78=""),"",B79/B78-1) -> -0.0061144412 | N79: =IF(OR(C79="",C78=""),"",C79/C78-1) -> -0.001863543 | O79: =IF(OR(D79="",D78=""),"",D79/D78-1) -> -0.0015015905 | P79: =IF(OR(F79="",F78=""),"",F79/F78-1) | Q79: =IF(OR(G79="",G78=""),"",G79/G78-1) -> -0.034482759 | R79: =IF(OR(H79="",H78=""),"",H79/H78-1) -> 0.01088647 | S79: =IF(OR(I79="",I78=""),"",I79/I78-1) | T79: =IF(OR(J79="",J78=""),"",J79/J78-1) | U79: =IF(OR(K79="",K78=""),"",K79/K78-1) | V79: =IF(OR(L79="",L78=""),"",L79/L78-1) | W79: =IF(COUNT(O75:O79)<5,"",STDEV(O75:O79)) | X79: =IF(W79="","",IF(W79>Controls!$B$2,1,0))
A80: 34808 | B80: 816.55 | C80: 2883.67 | D80: 504.92 | E80: 13.09 | G80: 0.27 | H80: 6.55 | M80: =IF(OR(B80="",B79=""),"",B80/B79-1) -> -0.011129411 | N80: =IF(OR(C80="",C79=""),"",C80/C79-1) -> -0.0011361471 | O80: =IF(OR(D80="",D79=""),"",D80/D79-1) -> -0.00089043671 | P80: =IF(OR(F80="",F79=""),"",F80/F79-1) | Q80: =IF(OR(G80="",G79=""),"",G80/G79-1) -> -0.035714286 | R80: =IF(OR(H80="",H79=""),"",H80/H79-1) -> 0.0076923077 | S80: =IF(OR(I80="",I79=""),"",I80/I79-1) | T80: =IF(OR(J80="",J79=""),"",J80/J79-1) | U80: =IF(OR(K80="",K79=""),"",K80/K79-1) | V80: =IF(OR(L80="",L79=""),"",L80/L79-1) | W80: =IF(COUNT(O76:O80)<5,"",STDEV(O76:O80)) | X80: =IF(W80="","",IF(W80>Controls!$B$2,1,0))
A81: 34809 | B81: 819.01 | C81: 2887.58 | D81: 505.29 | E81: 12.1 | G81: 0.28 | H81: 6.67 | M81: =IF(OR(B81="",B80=""),"",B81/B80-1) -> 0.0030126753 | N81: =IF(OR(C81="",C80=""),"",C81/C80-1) -> 0.001355911 | O81: =IF(OR(D81="",D80=""),"",D81/D80-1) -> 0.00073278935 | P81: =IF(OR(F81="",F80=""),"",F81/F80-1) | Q81: =IF(OR(G81="",G80=""),"",G81/G80-1) -> 0.037037037 | R81: =IF(OR(H81="",H80=""),"",H81/H80-1) -> 0.018320611 | S81: =IF(OR(I81="",I80=""),"",I81/I80-1) | T81: =IF(OR(J81="",J80=""),"",J81/J80-1) | U81: =IF(OR(K81="",K80=""),"",K81/K80-1) | V81: =IF(OR(L81="",L80=""),"",L81/L80-1) | W81: =IF(COUNT(O77:O81)<5,"",STDEV(O77:O81)) | X81: =IF(W81="","",IF(W81>Controls!$B$2,1,0))
A82: 34810 | B82: 823.44 | C82: 2905.24 | D82: 508.49 | E82: 11.86 | G82: 0.29 | H82: 6.62 | M82: =IF(OR(B82="",B81=""),"",B82/B81-1) -> 0.0054089694 | N82: =IF(OR(C82="",C81=""),"",C82/C81-1) -> 0.0061158479 | O82: =IF(OR(D82="",D81=""),"",D82/D81-1) -> 0.0063329969 | P82: =IF(OR(F82="",F81=""),"",F82/F81-1) | Q82: =IF(OR(G82="",G81=""),"",G82/G81-1) -> 0.035714286 | R82: =IF(OR(H82="",H81=""),"",H82/H81-1) -> -0.0074962519 | S82: =IF(OR(I82="",I81=""),"",I82/I81-1) | T82: =IF(OR(J82="",J81=""),"",J82/J81-1) | U82: =IF(OR(K82="",K81=""),"",K82/K81-1) | V82: =IF(OR(L82="",L81=""),"",L82/L81-1) | W82: =IF(COUNT(O78:O82)<5,"",STDEV(O78:O82)) | X82: =IF(W82="","",IF(W82>Controls!$B$2,1,0))
...

Sheet Controls
A1: Parameter | B1: Value | C1: Description
A2: Risk Threshold | B2: 0.02 | C2: Risk = 1 when 5-day S&P500 volatility exceeds this threshold
A3: Volatility Window (days) | B3: 5 | C3: Used in the rolling standard deviation formula for sp500_volatility_5d
